ERROR    sample_parser.py[LINE:18 2020-10-04 18:05-37][MainProcess][get_html] Error received html https://www.flashscore.com/match/fyXBxdlb/#point-by-point;1
Traceback (most recent call last):
  File "/home/max/.cache/pypoetry/virtualenvs/tennis-stat-scraper-G8qS3J8V-py3.8/lib/python3.8/site-packages/selenium/webdriver/common/service.py", line 72, in start
    self.process = subprocess.Popen(cmd, env=self.env,
  File "/usr/lib/python3.8/subprocess.py", line 854, in __init__
    self._execute_child(args, executable, preexec_fn, close_fds,
  File "/usr/lib/python3.8/subprocess.py", line 1702, in _execute_child
    raise child_exception_type(errno_num, err_msg, err_filename)
FileNotFoundError: [Errno 2] No such file or directory: './chromedriver'

During handling of the above exception, another exception occurred:

Traceback (most recent call last):
  File "stat_scraper/sample_parser.py", line 12, in get_html
    with get_driver() as driver:
  File "/home/max/projects/tennis-stat-scraper/stat_scraper/init_driver.py", line 10, in get_driver
    driver = webdriver.Chrome(options=chrome_options,
  File "/home/max/.cache/pypoetry/virtualenvs/tennis-stat-scraper-G8qS3J8V-py3.8/lib/python3.8/site-packages/selenium/webdriver/chrome/webdriver.py", line 73, in __init__
    self.service.start()
  File "/home/max/.cache/pypoetry/virtualenvs/tennis-stat-scraper-G8qS3J8V-py3.8/lib/python3.8/site-packages/selenium/webdriver/common/service.py", line 81, in start
    raise WebDriverException(
selenium.common.exceptions.WebDriverException: Message: 'chromedriver' executable needs to be in PATH. Please see https://sites.google.com/a/chromium.org/chromedriver/home

